Workbook

Sheet 작성가이드
A1: 바른발성연구소 · 훈련 스킬 트리 입력 시트
A3: ■ 어디에 적나요
A4: [스킬트리] 시트에만 적으시면 됩니다. 노란색 칸 = 직접 입력 / 회색 칸 = 자동 (건드리지 마세요)
A5: [계열정의] 계열 이름·색·해금 조건·소개 문구.
A6: [참조_훈련목록] 훈련명 모음. 스킬명 드롭다운이 여기서 나옵니다. 새 훈련은 여기에 먼저 추가.
A7: [참조_스케일목록] 앱에 들어있는 스케일 목록. 보기 전용.
A9: ■ 구조
A10: 계열 = 판 하나 (저음 / 중음 / 고음 / 성대결절 케어).
A11: 층 = 해금 단계. 위에서 아래로 내려갑니다.
A12: 자리 = 그 층에서 가로 위치. 1 ~ 5 사이, 0.5 단위 (1, 1.5, 2, 2.5 … 5).
A13: 윗층 두 갈래가 아래에서 하나로 모일 때 가운데(1.5 등)에 두면 선이 예쁘게 모입니다.
A14: 같은 계열·같은 층·같은 자리는 하나만 존재할 수 있습니다.
... A71: 비워두면 호흡 진도와 상관없이 처음부터 열립니다.

Sheet 스킬트리
A1: 훈련 스킬 트리 입력표 노란칸=직접 입력 / 회색칸=자동 (수정하지 마세요) | T1: 스케일ID | U1: 스케일명 | V1: 음역 | X1: 넘버 | Y1: 훈련명
A2: 계열 | B2: 층 | C2: 자리 | D2: 스킬ID | E2: 스킬명 | F2: 스케일ID (공용/여) | G2: 스케일ID (남) | H2: 스케일명(자동) | I2: 반복 | J2: 완료최소횟수 | K2: 선행스킬1 | L2: 선행스킬2 | M2: 선행스킬3 | N2: 타계열선행 | O2: 호흡해금일차 | P2: 상태 | Q2: 메모 | R2: 검사 | T2: 3D-A | U2: 3도 스케일 | V2: 흉성(여자) | X2: 1 | Y2: 가슴 소리 만들기
A3: 저음 | B3: 1 | C3: 3 | D3: L1-3 | E3: 소울음소리 | H3: =IF($F3="","",IF($G3="",IFERROR(INDEX(참조_스케일목록!$B:$B,MATCH($F3,참조_스케일목록!$A:$A,0))&" ("&INDEX(참조_스케일목록!$C:$C,MATCH($F3,참조_스케일목록!$A:$A,0))&")","※없는 ID"),"여 "&IFERROR(INDEX(참조_스케일목록!$B:$B,MATCH($F3,참조_스케일목록!$A:$A,0))&" ("&INDEX(참조_스케일목록!$C:$C,MATCH($F3,참조_스케일목록!$A:$A,0))&")","※없는 ID")&" / 남 "&IFERROR(INDEX(참조_스케일목록!$B:$B,MATCH($G3,참조_스케일목록!$A:$A,0))&" ("&INDEX(참조_스케일목록!$C:$C,MATCH($G3,참조_스케일목록!$A:$A,0))&")","※없는 ID"))) | I3: 10 | J3: 7 | O3: 13 | P3: 공개 | R3: =IF($A3="","",IF(AND($C3<>"",OR($C3<1,$C3>5,MOD($C3*2,1)<>0)),"자리는 1~5 (0.5단위)",IF(COUNTIFS($A$3:$A$170,$A3,$B$3:$B$170,$B3,$C$3:$C$170,$C3)>1,"같은 자리 중복",IF($D3="","스킬ID 비었음",IF(COUNTIF($D$3:$D$170,$D3)>1,"스킬ID 중복",IF(AND($G3<>"",$F3=""),"여 스케일도 필요",IF(AND($K3<>"",ISNA(MATCH($K3,$D$3:$D$170,0))),"선행스킬1 없음",IF(AND($L3<>"",ISNA(MATCH($L3,$D$3:$D$170,0))),"선행스킬2 없음",IF(AND($N3<>"",ISNA(MATCH($N3,$D$3:$D$170,0))),"타계열선행 없음","OK"))))))))) -> OK | T3: 3D-B | U3: 3도 스케일 | V3: 흉성(남) | X3: 2 | Y3: 발성훈련 셋팅
A4: 저음 | B4: 2 | C4: 1 | D4: L2-1 | E4: 우~우~우~ | H4: =IF($F4="","",IF($G4="",IFERROR(INDEX(참조_스케일목록!$B:$B,MATCH($F4,참조_스케일목록!$A:$A,0))&" ("&INDEX(참조_스케일목록!$C:$C,MATCH($F4,참조_스케일목록!$A:$A,0))&")","※없는 ID"),"여 "&IFERROR(INDEX(참조_스케일목록!$B:$B,MATCH($F4,참조_스케일목록!$A:$A,0))&" ("&INDEX(참조_스케일목록!$C:$C,MATCH($F4,참조_스케일목록!$A:$A,0))&")","※없는 ID")&" / 남 "&IFERROR(INDEX(참조_스케일목록!$B:$B,MATCH($G4,참조_스케일목록!$A:$A,0))&" ("&INDEX(참조_스케일목록!$C:$C,MATCH($G4,참조_스케일목록!$A:$A,0))&")","※없는 ID"))) | I4: 10 | J4: 7 | K4: L1-3 | P4: 공개 | R4: =IF($A4="","",IF(AND($C4<>"",OR($C4<1,$C4>5,MOD($C4*2,1)<>0)),"자리는 1~5 (0.5단위)",IF(COUNTIFS($A$3:$A$170,$A4,$B$3:$B$170,$B4,$C$3:$C$170,$C4)>1,"같은 자리 중복",IF($D4="","스킬ID 비었음",IF(COUNTIF($D$3:$D$170,$D4)>1,"스킬ID 중복",IF(AND($G4<>"",$F4=""),"여 스케일도 필요",IF(AND($K4<>"",ISNA(MATCH($K4,$D$3:$D$170,0))),"선행스킬1 없음",IF(AND($L4<>"",ISNA(MATCH($L4,$D$3:$D$170,0))),"선행스킬2 없음",IF(AND($N4<>"",ISNA(MATCH($N4,$D$3:$D$170,0))),"타계열선행 없음","OK"))))))))) -> OK | T4: 3D-C | U4: 3도 스케일 | V4: 흉성~낮은중성 | X4: 3 | Y4: 흉복식호흡
A5: 저음 | B5: 2 | C5: 2 | D5: L2-2 | P5: 공개 | R5: =IF($A5="","",IF(AND($C5<>"",OR($C5<1,$C5>5,MOD($C5*2,1)<>0)),"자리는 1~5 (0.5단위)",IF(COUNTIFS($A$3:$A$170,$A5,$B$3:$B$170,$B5,$C$3:$C$170,$C5)>1,"같은 자리 중복",IF($D5="","스킬ID 비었음",IF(COUNTIF($D$3:$D$170,$D5)>1,"스킬ID 중복",IF(AND($G5<>"",$F5=""),"여 스케일도 필요",IF(AND($K5<>"",ISNA(MATCH($K5,$D$3:$D$170,0))),"선행스킬1 없음",IF(AND($L5<>"",ISNA(MATCH($L5,$D$3:$D$170,0))),"선행스킬2 없음",IF(AND($N5<>"",ISNA(MATCH($N5,$D$3:$D$170,0))),"타계열선행 없음","OK"))))))))) -> OK | T5: 3D-D | U5: 3도 스케일 | V5: 흉성~높은중성 | X5: 4 | Y5: 주먹쥐고 호흡
A6: 저음 | B6: 2 | C6: 3 | D6: L2-3 | E6: 립트릴 | F6: 5D-A | G6: 5D-J | H6: =IF($F6="","",IF($G6="",IFERROR(INDEX(참조_스케일목록!$B:$B,MATCH($F6,참조_스케일목록!$A:$A,0))&" ("&INDEX(참조_스케일목록!$C:$C,MATCH($F6,참조_스케일목록!$A:$A,0))&")","※없는 ID"),"여 "&IFERROR(INDEX(참조_스케일목록!$B:$B,MATCH($F6,참조_스케일목록!$A:$A,0))&" ("&INDEX(참조_스케일목록!$C:$C,MATCH($F6,참조_스케일목록!$A:$A,0))&")","※없는 ID")&" / 남 "&IFERROR(INDEX(참조_스케일목록!$B:$B,MATCH($G6,참조_스케일목록!$A:$A,0))&" ("&INDEX(참조_스케일목록!$C:$C,MATCH($G6,참조_스케일목록!$A:$A,0))&")","※없는 ID"))) -> 여 5도 스케일 (흉성(여자)) / 남 5도 스케일 (흉성(남자)) | I6: 1 | J6: 7 | K6: L1-3 | P6: 공개 | R6: =IF($A6="","",IF(AND($C6<>"",OR($C6<1,$C6>5,MOD($C6*2,1)<>0)),"자리는 1~5 (0.5단위)",IF(COUNTIFS($A$3:$A$170,$A6,$B$3:$B$170,$B6,$C$3:$C$170,$C6)>1,"같은 자리 중복",IF($D6="","스킬ID 비었음",IF(COUNTIF($D$3:$D$170,$D6)>1,"스킬ID 중복",IF(AND($G6<>"",$F6=""),"여 스케일도 필요",IF(AND($K6<>"",ISNA(MATCH($K6,$D$3:$D$170,0))),"선행스킬1 없음",IF(AND($L6<>"",ISNA(MATCH($L6,$D$3:$D$170,0))),"선행스킬2 없음",IF(AND($N6<>"",ISNA(MATCH($N6,$D$3:$D$170,0))),"타계열선행 없음","OK"))))))))) -> OK | T6: 3D-E | U6: 3도 스케일 | V6: 낮은중성 | X6: 5 | Y6: 호흡 저항 도구 훈련
A7: 저음 | B7: 2 | C7: 4 | D7: L2-4 | H7: =IF($F7="","",IF($G7="",IFERROR(INDEX(참조_스케일목록!$B:$B,MATCH($F7,참조_스케일목록!$A:$A,0))&" ("&INDEX(참조_스케일목록!$C:$C,MATCH($F7,참조_스케일목록!$A:$A,0))&")","※없는 ID"),"여 "&IFERROR(INDEX(참조_스케일목록!$B:$B,MATCH($F7,참조_스케일목록!$A:$A,0))&" ("&INDEX(참조_스케일목록!$C:$C,MATCH($F7,참조_스케일목록!$A:$A,0))&")","※없는 ID")&" / 남 "&IFERROR(INDEX(참조_스케일목록!$B:$B,MATCH($G7,참조_스케일목록!$A:$A,0))&" ("&INDEX(참조_스케일목록!$C:$C,MATCH($G7,참조_스케일목록!$A:$A,0))&")","※없는 ID"))) | P7: 공개 | R7: =IF($A7="","",IF(AND($C7<>"",OR($C7<1,$C7>5,MOD($C7*2,1)<>0)),"자리는 1~5 (0.5단위)",IF(COUNTIFS($A$3:$A$170,$A7,$B$3:$B$170,$B7,$C$3:$C$170,$C7)>1,"같은 자리 중복",IF($D7="","스킬ID 비었음",IF(COUNTIF($D$3:$D$170,$D7)>1,"스킬ID 중복",IF(AND($G7<>"",$F7=""),"여 스케일도 필요",IF(AND($K7<>"",ISNA(MATCH($K7,$D$3:$D$170,0))),"선행스킬1 없음",IF(AND($L7<>"",ISNA(MATCH($L7,$D$3:$D$170,0))),"선행스킬2 없음",IF(AND($N7<>"",ISNA(MATCH($N7,$D$3:$D$170,0))),"타계열선행 없음","OK"))))))))) -> OK | T7: 3D-F | U7: 3도 스케일 | V7: 높은중성 | X7: 6 | Y7: 립트릴
A8: 저음 | B8: 2 | C8: 5 | D8: L2-5 | E8: 아~아~아~ | H8: =IF($F8="","",IF($G8="",IFERROR(INDEX(참조_스케일목록!$B:$B,MATCH($F8,참조_스케일목록!$A:$A,0))&" ("&INDEX(참조_스케일목록!$C:$C,MATCH($F8,참조_스케일목록!$A:$A,0))&")","※없는 ID"),"여 "&IFERROR(INDEX(참조_스케일목록!$B:$B,MATCH($F8,참조_스케일목록!$A:$A,0))&" ("&INDEX(참조_스케일목록!$C:$C,MATCH($F8,참조_스케일목록!$A:$A,0))&")","※없는 ID")&" / 남 "&IFERROR(INDEX(참조_스케일목록!$B:$B,MATCH($G8,참조_스케일목록!$A:$A,0))&" ("&INDEX(참조_스케일목록!$C:$C,MATCH($G8,참조_스케일목록!$A:$A,0))&")","※없는 ID"))) | I8: 10 | J8: 7 | K8: L1-3 | P8: 공개 | R8: =IF($A8="","",IF(AND($C8<>"",OR($C8<1,$C8>5,MOD($C8*2,1)<>0)),"자리는 1~5 (0.5단위)",IF(COUNTIFS($A$3:$A$170,$A8,$B$3:$B$170,$B8,$C$3:$C$170,$C8)>1,"같은 자리 중복",IF($D8="","스킬ID 비었음",IF(COUNTIF($D$3:$D$170,$D8)>1,"스킬ID 중복",IF(AND($G8<>"",$F8=""),"여 스케일도 필요",IF(AND($K8<>"",ISNA(MATCH($K8,$D$3:$D$170,0))),"선행스킬1 없음",IF(AND($L8<>"",ISNA(MATCH($L8,$D$3:$D$170,0))),"선행스킬2 없음",IF(AND($N8<>"",ISNA(MATCH($N8,$D$3:$D$170,0))),"타계열선행 없음","OK"))))))))) -> OK | T8: 3D-G | U8: 3도 스케일 | V8: 흉성~낮은두성 | X8: 7 | Y8: 립트릴 1번
A9: 저음 | B9: 3 | C9: 1 | D9: L3-1 | E9: 강한 우~우~우~ | H9: =IF($F9="","",IF($G9="",IFERROR(INDEX(참조_스케일목록!$B:$B,MATCH($F9,참조_스케일목록!$A:$A,0))&" ("&INDEX(참조_스케일목록!$C:$C,MATCH($F9,참조_스케일목록!$A:$A,0))&")","※없는 ID"),"여 "&IFERROR(INDEX(참조_스케일목록!$B:$B,MATCH($F9,참조_스케일목록!$A:$A,0))&" ("&INDEX(참조_스케일목록!$C:$C,MATCH($F9,참조_스케일목록!$A:$A,0))&")","※없는 ID")&" / 남 "&IFERROR(INDEX(참조_스케일목록!$B:$B,MATCH($G9,참조_스케일목록!$A:$A,0))&" ("&INDEX(참조_스케일목록!$C:$C,MATCH($G9,참조_스케일목록!$A:$A,0))&")","※없는 ID"))) | I9: 1 | J9: 7 | P9: 준비중 | R9: =IF($A9="","",IF(AND($C9<>"",OR($C9<1,$C9>5,MOD($C9*2,1)<>0)),"자리는 1~5 (0.5단위)",IF(COUNTIFS($A$3:$A$170,$A9,$B$3:$B$170,$B9,$C$3:$C$170,$C9)>1,"같은 자리 중복",IF($D9="","스킬ID 비었음",IF(COUNTIF($D$3:$D$170,$D9)>1,"스킬ID 중복",IF(AND($G9<>"",$F9=""),"여 스케일도 필요",IF(AND($K9<>"",ISNA(MATCH($K9,$D$3:$D$170,0))),"선행스킬1 없음",IF(AND($L9<>"",ISNA(MATCH($L9,$D$3:$D$170,0))),"선행스킬2 없음",IF(AND($N9<>"",ISNA(MATCH($N9,$D$3:$D$170,0))),"타계열선행 없음","OK"))))))))) -> OK | T9: 3D-H | U9: 3도 스케일 | V9: 흉성~높은두성 | X9: 8 | Y9: 립트릴 2번
A10: 저음 | B10: 3 | C10: 2 | D10: L3-2 | H10: =IF($F10="","",IF($G10="",IFERROR(INDEX(참조_스케일목록!$B:$B,MATCH($F10,참조_스케일목록!$A:$A,0))&" ("&INDEX(참조_스케일목록!$C:$C,MATCH($F10,참조_스케일목록!$A:$A,0))&")","※없는 ID"),"여 "&IFERROR(INDEX(참조_스케일목록!$B:$B,MATCH($F10,참조_스케일목록!$A:$A,0))&" ("&INDEX(참조_스케일목록!$C:$C,MATCH($F10,참조_스케일목록!$A:$A,0))&")","※없는 ID")&" / 남 "&IFERROR(INDEX(참조_스케일목록!$B:$B,MATCH($G10,참조_스케일목록!$A:$A,0))&" ("&INDEX(참조_스케일목록!$C:$C,MATCH($G10,참조_스케일목록!$A:$A,0))&")","※없는 ID"))) | P10: 준비중 | R10: =IF($A10="","",IF(AND($C10<>"",OR($C10<1,$C10>5,MOD($C10*2,1)<>0)),"자리는 1~5 (0.5단위)",IF(COUNTIFS($A$3:$A$170,$A10,$B$3:$B$170,$B10,$C$3:$C$170,$C10)>1,"같은 자리 중복",IF($D10="","스킬ID 비었음",IF(COUNTIF($D$3:$D$170,$D10)>1,"스킬ID 중복",IF(AND($G10<>"",$F10=""),"여 스케일도 필요",IF(AND($K10<>"",ISNA(MATCH($K10,$D$3:$D$170,0))),"선행스킬1 없음",IF(AND($L10<>"",ISNA(MATCH($L10,$D$3:$D$170,0))),"선행스킬2 없음",IF(AND($N10<>"",ISNA(MATCH($N10,$D$3:$D$170,0))),"타계열선행 없음","OK"))))))))) -> OK | T10: 3D-I | U10: 3도 스케일 | V10: 흉성(여자) | X10: 9 | Y10: 립트릴 3번
A11: 저음 | B11: 3 | C11: 3 | D11: L3-3 | E11: 립트릴 | F11: 3D-A | G11: 3D-B | H11: =IF($F11="","",IF($G11="",IFERROR(INDEX(참조_스케일목록!$B:$B,MATCH($F11,참조_스케일목록!$A:$A,0))&" ("&INDEX(참조_스케일목록!$C:$C,MATCH($F11,참조_스케일목록!$A:$A,0))&")","※없는 ID"),"여 "&IFERROR(INDEX(참조_스케일목록!$B:$B,MATCH($F11,참조_스케일목록!$A:$A,0))&" ("&INDEX(참조_스케일목록!$C:$C,MATCH($F11,참조_스케일목록!$A:$A,0))&")","※없는 ID")&" / 남 "&IFERROR(INDEX(참조_스케일목록!$B:$B,MATCH($G11,참조_스케일목록!$A:$A,0))&" ("&INDEX(참조_스케일목록!$C:$C,MATCH($G11,참조_스케일목록!$A:$A,0))&")","※없는 ID"))) -> 여 3도 스케일 (흉성(여자)) / 남 3도 스케일 (흉성(남)) | I11: 1 | J11: 7 | P11: 준비중 | R11: =IF($A11="","",IF(AND($C11<>"",OR($C11<1,$C11>5,MOD($C11*2,1)<>0)),"자리는 1~5 (0.5단위)",IF(COUNTIFS($A$3:$A$170,$A11,$B$3:$B$170,$B11,$C$3:$C$170,$C11)>1,"같은 자리 중복",IF($D11="","스킬ID 비었음",IF(COUNTIF($D$3:$D$170,$D11)>1,"스킬ID 중복",IF(AND($G11<>"",$F11=""),"여 스케일도 필요",IF(AND($K11<>"",ISNA(MATCH($K11,$D$3:$D$170,0))),"선행스킬1 없음",IF(AND($L11<>"",ISNA(MATCH($L11,$D$3:$D$170,0))),"선행스킬2 없음",IF(AND($N11<>"",ISNA(MATCH($N11,$D$3:$D$170,0))),"타계열선행 없음","OK"))))))))) -> OK | T11: 5D-A | U11: 5도 스케일 | V11: 흉성(여자) | X11: 10 | Y11: 립트릴 4번
A12: 저음 | B12: 3 | C12: 4 | D12: L3-4 | H12: =IF($F12="","",IF($G12="",IFERROR(INDEX(참조_스케일목록!$B:$B,MATCH($F12,참조_스케일목록!$A:$A,0))&" ("&INDEX(참조_스케일목록!$C:$C,MATCH($F12,참조_스케일목록!$A:$A,0))&")","※없는 ID"),"여 "&IFERROR(INDEX(참조_스케일목록!$B:$B,MATCH($F12,참조_스케일목록!$A:$A,0))&" ("&INDEX(참조_스케일목록!$C:$C,MATCH($F12,참조_스케일목록!$A:$A,0))&")","※없는 ID")&" / 남 "&IFERROR(INDEX(참조_스케일목록!$B:$B,MATCH($G12,참조_스케일목록!$A:$A,0))&" ("&INDEX(참조_스케일목록!$C:$C,MATCH($G12,참조_스케일목록!$A:$A,0))&")","※없는 ID"))) | P12: 준비중 | R12: =IF($A12="","",IF(AND($C12<>"",OR($C12<1,$C12>5,MOD($C12*2,1)<>0)),"자리는 1~5 (0.5단위)",IF(COUNTIFS($A$3:$A$170,$A12,$B$3:$B$170,$B12,$C$3:$C$170,$C12)>1,"같은 자리 중복",IF($D12="","스킬ID 비었음",IF(COUNTIF($D$3:$D$170,$D12)>1,"스킬ID 중복",IF(AND($G12<>"",$F12=""),"여 스케일도 필요",IF(AND($K12<>"",ISNA(MATCH($K12,$D$3:$D$170,0))),"선행스킬1 없음",IF(AND($L12<>"",ISNA(MATCH($L12,$D$3:$D$170,0))),"선행스킬2 없음",IF(AND($N12<>"",ISNA(MATCH($N12,$D$3:$D$170,0))),"타계열선행 없음","OK"))))))))) -> OK | T12: 5D-J | U12: 5도 스케일 | V12: 흉성(남자) | X12: 11 | Y12: S로 호흡 뱉기
A13: 저음 | B13: 3 | C13: 5 | D13: L3-5 | E13: 강한 아~아~아~ | H13: =IF($F13="","",IF($G13="",IFERROR(INDEX(참조_스케일목록!$B:$B,MATCH($F13,참조_스케일목록!$A:$A,0))&" ("&INDEX(참조_스케일목록!$C:$C,MATCH($F13,참조_스케일목록!$A:$A,0))&")","※없는 ID"),"여 "&IFERROR(INDEX(참조_스케일목록!$B:$B,MATCH($F13,참조_스케일목록!$A:$A,0))&" ("&INDEX(참조_스케일목록!$C:$C,MATCH($F13,참조_스케일목록!$A:$A,0))&")","※없는 ID")&" / 남 "&IFERROR(INDEX(참조_스케일목록!$B:$B,MATCH($G13,참조_스케일목록!$A:$A,0))&" ("&INDEX(참조_스케일목록!$C:$C,MATCH($G13,참조_스케일목록!$A:$A,0))&")","※없는 ID"))) | I13: 1 | J13: 7 | P13: 준비중 | R13: =IF($A13="","",IF(AND($C13<>"",OR($C13<1,$C13>5,MOD($C13*2,1)<>0)),"자리는 1~5 (0.5단위)",IF(COUNTIFS($A$3:$A$170,$A13,$B$3:$B$170,$B13,$C$3:$C$170,$C13)>1,"같은 자리 중복",IF($D13="","스킬ID 비었음",IF(COUNTIF($D$3:$D$170,$D13)>1,"스킬ID 중복",IF(AND($G13<>"",$F13=""),"여 스케일도 필요",IF(AND($K13<>"",ISNA(MATCH($K13,$D$3:$D$170,0))),"선행스킬1 없음",IF(AND($L13<>"",ISNA(MATCH($L13,$D$3:$D$170,0))),"선행스킬2 없음",IF(AND($N13<>"",ISNA(MATCH($N13,$D$3:$D$170,0))),"타계열선행 없음","OK"))))))))) -> OK | T13: 5D-B | U13: 5도 스케일 | V13: 흉성~낮은두성 | X13: 12 | Y13: S로 스타카토 호흡뱉기
A14: 저음 | B14: 4 | C14: 1 | D14: L4-1 | E14: 강한 우(앞) | F14: 3D-A | G14: 3D-B | H14: =IF($F14="","",IF($G14="",IFERROR(INDEX(참조_스케일목록!$B:$B,MATCH($F14,참조_스케일목록!$A:$A,0))&" ("&INDEX(참조_스케일목록!$C:$C,MATCH($F14,참조_스케일목록!$A:$A,0))&")","※없는 ID"),"여 "&IFERROR(INDEX(참조_스케일목록!$B:$B,MATCH($F14,참조_스케일목록!$A:$A,0))&" ("&INDEX(참조_스케일목록!$C:$C,MATCH($F14,참조_스케일목록!$A:$A,0))&")","※없는 ID")&" / 남 "&IFERROR(INDEX(참조_스케일목록!$B:$B,MATCH($G14,참조_스케일목록!$A:$A,0))&" ("&INDEX(참조_스케일목록!$C:$C,MATCH($G14,참조_스케일목록!$A:$A,0))&")","※없는 ID"))) -> 여 3도 스케일 (흉성(여자)) / 남 3도 스케일 (흉성(남)) | I14: 1 | J14: 7 | P14: 준비중 | R14: =IF($A14="","",IF(AND($C14<>"",OR($C14<1,$C14>5,MOD($C14*2,1)<>0)),"자리는 1~5 (0.5단위)",IF(COUNTIFS($A$3:$A$170,$A14,$B$3:$B$170,$B14,$C$3:$C$170,$C14)>1,"같은 자리 중복",IF($D14="","스킬ID 비었음",IF(COUNTIF($D$3:$D$170,$D14)>1,"스킬ID 중복",IF(AND($G14<>"",$F14=""),"여 스케일도 필요",IF(AND($K14<>"",ISNA(MATCH($K14,$D$3:$D$170,0))),"선행스킬1 없음",IF(AND($L14<>"",ISNA(MATCH($L14,$D$3:$D$170,0))),"선행스킬2 없음",IF(AND($N14<>"",ISNA(MATCH($N14,$D$3:$D$170,0))),"타계열선행 없음","OK"))))))))) -> OK | T14: 5D-C | U14: 5도 스케일 | V14: 흉성~높은두성 | X14: 13 | Y14: S로 소리내기
A15: 저음 | B15: 4 | C15: 2 | D15: L4-2 | P15: 준비중 | R15: =IF($A15="","",IF(AND($C15<>"",OR($C15<1,$C15>5,MOD($C15*2,1)<>0)),"자리는 1~5 (0.5단위)",IF(COUNTIFS($A$3:$A$170,$A15,$B$3:$B$170,$B15,$C$3:$C$170,$C15)>1,"같은 자리 중복",IF($D15="","스킬ID 비었음",IF(COUNTIF($D$3:$D$170,$D15)>1,"스킬ID 중복",IF(AND($G15<>"",$F15=""),"여 스케일도 필요",IF(AND($K15<>"",ISNA(MATCH($K15,$D$3:$D$170,0))),"선행스킬1 없음",IF(AND($L15<>"",ISNA(MATCH($L15,$D$3:$D$170,0))),"선행스킬2 없음",IF(AND($N15<>"",ISNA(MATCH($N15,$D$3:$D$170,0))),"타계열선행 없음","OK"))))))))) -> OK | T15: 5D-D | U15: 5도 스케일 | V15: 흉성~휘슬 | X15: 14 | Y15: Z 스타카토 소리내기
A16: 저음 | B16: 4 | C16: 3 | D16: L4-3 | H16: =IF($F16="","",IF($G16="",IFERROR(INDEX(참조_스케일목록!$B:$B,MATCH($F16,참조_스케일목록!$A:$A,0))&" ("&INDEX(참조_스케일목록!$C:$C,MATCH($F16,참조_스케일목록!$A:$A,0))&")","※없는 ID"),"여 "&IFERROR(INDEX(참조_스케일목록!$B:$B,MATCH($F16,참조_스케일목록!$A:$A,0))&" ("&INDEX(참조_스케일목록!$C:$C,MATCH($F16,참조_스케일목록!$A:$A,0))&")","※없는 ID")&" / 남 "&IFERROR(INDEX(참조_스케일목록!$B:$B,MATCH($G16,참조_스케일목록!$A:$A,0))&" ("&INDEX(참조_스케일목록!$C:$C,MATCH($G16,참조_스케일목록!$A:$A,0))&")","※없는 ID"))) | P16: 준비중 | R16: =IF($A16="","",IF(AND($C16<>"",OR($C16<1,$C16>5,MOD($C16*2,1)<>0)),"자리는 1~5 (0.5단위)",IF(COUNTIFS($A$3:$A$170,$A16,$B$3:$B$170,$B16,$C$3:$C$170,$C16)>1,"같은 자리 중복",IF($D16="","스킬ID 비었음",IF(COUNTIF($D$3:$D$170,$D16)>1,"스킬ID 중복",IF(AND($G16<>"",$F16=""),"여 스케일도 필요",IF(AND($K16<>"",ISNA(MATCH($K16,$D$3:$D$170,0))),"선행스킬1 없음",IF(AND($L16<>"",ISNA(MATCH($L16,$D$3:$D$170,0))),"선행스킬2 없음",IF(AND($N16<>"",ISNA(MATCH($N16,$D$3:$D$170,0))),"타계열선행 없음","OK"))))))))) -> OK | T16: 5D-E | U16: 5도 스케일 | V16: 중성~낮은중성 | X16: 15 | Y16: Z 한음 유지
A17: 저음 | B17: 4 | C17: 4 | D17: L4-4 | H17: =IF($F17="","",IF($G17="",IFERROR(INDEX(참조_스케일목록!$B:$B,MATCH($F17,참조_스케일목록!$A:$A,0))&" ("&INDEX(참조_스케일목록!$C:$C,MATCH($F17,참조_스케일목록!$A:$A,0))&")","※없는 ID"),"여 "&IFERROR(INDEX(참조_스케일목록!$B:$B,MATCH($F17,참조_스케일목록!$A:$A,0))&" ("&INDEX(참조_스케일목록!$C:$C,MATCH($F17,참조_스케일목록!$A:$A,0))&")","※없는 ID")&" / 남 "&IFERROR(INDEX(참조_스케일목록!$B:$B,MATCH($G17,참조_스케일목록!$A:$A,0))&" ("&INDEX(참조_스케일목록!$C:$C,MATCH($G17,참조_스케일목록!$A:$A,0))&")","※없는 ID"))) | P17: 준비중 | R17: =IF($A17="","",IF(AND($C17<>"",OR($C17<1,$C17>5,MOD($C17*2,1)<>0)),"자리는 1~5 (0.5단위)",IF(COUNTIFS($A$3:$A$170,$A17,$B$3:$B$170,$B17,$C$3:$C$170,$C17)>1,"같은 자리 중복",IF($D17="","스킬ID 비었음",IF(COUNTIF($D$3:$D$170,$D17)>1,"스킬ID 중복",IF(AND($G17<>"",$F17=""),"여 스케일도 필요",IF(AND($K17<>"",ISNA(MATCH($K17,$D$3:$D$170,0))),"선행스킬1 없음",IF(AND($L17<>"",ISNA(MATCH($L17,$D$3:$D$170,0))),"선행스킬2 없음",IF(AND($N17<>"",ISNA(MATCH($N17,$D$3:$D$170,0))),"타계열선행 없음","OK"))))))))) -> OK | T17: 5D-F | U17: 5도 스케일 | V17: 중성~높은중성 | X17: 16 | Y17: Z 소리내기
A18: 저음 | B18: 4 | C18: 5 | D18: L4-5 | E18: 강한 아(앞) | F18: 3D-A | G18: 3D-B | H18: =IF($F18="","",IF($G18="",IFERROR(INDEX(참조_스케일목록!$B:$B,MATCH($F18,참조_스케일목록!$A:$A,0))&" ("&INDEX(참조_스케일목록!$C:$C,MATCH($F18,참조_스케일목록!$A:$A,0))&")","※없는 ID"),"여 "&IFERROR(INDEX(참조_스케일목록!$B:$B,MATCH($F18,참조_스케일목록!$A:$A,0))&" ("&INDEX(참조_스케일목록!$C:$C,MATCH($F18,참조_스케일목록!$A:$A,0))&")","※없는 ID")&" / 남 "&IFERROR(INDEX(참조_스케일목록!$B:$B,MATCH($G18,참조_스케일목록!$A:$A,0))&" ("&INDEX(참조_스케일목록!$C:$C,MATCH($G18,참조_스케일목록!$A:$A,0))&")","※없는 ID"))) -> 여 3도 스케일 (흉성(여자)) / 남 3도 스케일 (흉성(남)) | I18: 1 | J18: 7 | P18: 준비중 | R18: =IF($A18="","",IF(AND($C18<>"",OR($C18<1,$C18>5,MOD($C18*2,1)<>0)),"자리는 1~5 (0.5단위)",IF(COUNTIFS($A$3:$A$170,$A18,$B$3:$B$170,$B18,$C$3:$C$170,$C18)>1,"같은 자리 중복",IF($D18="","스킬ID 비었음",IF(COUNTIF($D$3:$D$170,$D18)>1,"스킬ID 중복",IF(AND($G18<>"",$F18=""),"여 스케일도 필요",IF(AND($K18<>"",ISNA(MATCH($K18,$D$3:$D$170,0))),"선행스킬1 없음",IF(AND($L18<>"",ISNA(MATCH($L18,$D$3:$D$170,0))),"선행스킬2 없음",IF(AND($N18<>"",ISNA(MATCH($N18,$D$3:$D$170,0))),"타계열선행 없음","OK"))))))))) -> OK | T18: 5D-G | U18: 5도 스케일 | V18: 중성~낮은두성 | X18: 17 | Y18: 허밍
A19: 저음 | B19: 5 | C19: 1 | D19: L5-1 | E19: 강한 우(뒤) | F19: 3D-A | G19: 3D-B | H19: =IF($F19="","",IF($G19="",IFERROR(INDEX(참조_스케일목록!$B:$B,MATCH($F19,참조_스케일목록!$A:$A,0))&" ("&INDEX(참조_스케일목록!$C:$C,MATCH($F19,참조_스케일목록!$A:$A,0))&")","※없는 ID"),"여 "&IFERROR(INDEX(참조_스케일목록!$B:$B,MATCH($F19,참조_스케일목록!$A:$A,0))&" ("&INDEX(참조_스케일목록!$C:$C,MATCH($F19,참조_스케일목록!$A:$A,0))&")","※없는 ID")&" / 남 "&IFERROR(INDEX(참조_스케일목록!$B:$B,MATCH($G19,참조_스케일목록!$A:$A,0))&" ("&INDEX(참조_스케일목록!$C:$C,MATCH($G19,참조_스케일목록!$A:$A,0))&")","※없는 ID"))) -> 여 3도 스케일 (흉성(여자)) / 남 3도 스케일 (흉성(남)) | I19: 1 | J19: 7 | P19: 준비중 | R19: =IF($A19="","",IF(AND($C19<>"",OR($C19<1,$C19>5,MOD($C19*2,1)<>0)),"자리는 1~5 (0.5단위)",IF(COUNTIFS($A$3:$A$170,$A19,$B$3:$B$170,$B19,$C$3:$C$170,$C19)>1,"같은 자리 중복",IF($D19="","스킬ID 비었음",IF(COUNTIF($D$3:$D$170,$D19)>1,"스킬ID 중복",IF(AND($G19<>"",$F19=""),"여 스케일도 필요",IF(AND($K19<>"",ISNA(MATCH($K19,$D$3:$D$170,0))),"선행스킬1 없음",IF(AND($L19<>"",ISNA(MATCH($L19,$D$3:$D$170,0))),"선행스킬2 없음",IF(AND($N19<>"",ISNA(MATCH($N19,$D$3:$D$170,0))),"타계열선행 없음","OK"))))))))) -> OK | T19: 5D-H | U19: 5도 스케일 | V19: 중성~높은두성 | X19: 18 | Y19: 오픈 허밍
A20: 저음 | B20: 5 | C20: 2 | D20: L5-2 | P20: 준비중 | R20: =IF($A20="","",IF(AND($C20<>"",OR($C20<1,$C20>5,MOD($C20*2,1)<>0)),"자리는 1~5 (0.5단위)",IF(COUNTIFS($A$3:$A$170,$A20,$B$3:$B$170,$B20,$C$3:$C$170,$C20)>1,"같은 자리 중복",IF($D20="","스킬ID 비었음",IF(COUNTIF($D$3:$D$170,$D20)>1,"스킬ID 중복",IF(AND($G20<>"",$F20=""),"여 스케일도 필요",IF(AND($K20<>"",ISNA(MATCH($K20,$D$3:$D$170,0))),"선행스킬1 없음",IF(AND($L20<>"",ISNA(MATCH($L20,$D$3:$D$170,0))),"선행스킬2 없음",IF(AND($N20<>"",ISNA(MATCH($N20,$D$3:$D$170,0))),"타계열선행 없음","OK"))))))))) -> OK | T20: 5D-I | U20: 5도 스케일 | V20: 중성~휘슬 | X20: 19 | Y20: 오픈허밍 아~
A21: 저음 | B21: 5 | C21: 3 | D21: L5-3 | H21: =IF($F21="","",IF($G21="",IFERROR(INDEX(참조_스케일목록!$B:$B,MATCH($F21,참조_스케일목록!$A:$A,0))&" ("&INDEX(참조_스케일목록!$C:$C,MATCH($F21,참조_스케일목록!$A:$A,0))&")","※없는 ID"),"여 "&IFERROR(INDEX(참조_스케일목록!$B:$B,MATCH($F21,참조_스케일목록!$A:$A,0))&" ("&INDEX(참조_스케일목록!$C:$C,MATCH($F21,참조_스케일목록!$A:$A,0))&")","※없는 ID")&" / 남 "&IFERROR(INDEX(참조_스케일목록!$B:$B,MATCH($G21,참조_스케일목록!$A:$A,0))&" ("&INDEX(참조_스케일목록!$C:$C,MATCH($G21,참조_스케일목록!$A:$A,0))&")","※없는 ID"))) | P21: 준비중 | R21: =IF($A21="","",IF(AND($C21<>"",OR($C21<1,$C21>5,MOD($C21*2,1)<>0)),"자리는 1~5 (0.5단위)",IF(COUNTIFS($A$3:$A$170,$A21,$B$3:$B$170,$B21,$C$3:$C$170,$C21)>1,"같은 자리 중복",IF($D21="","스킬ID 비었음",IF(COUNTIF($D$3:$D$170,$D21)>1,"스킬ID 중복",IF(AND($G21<>"",$F21=""),"여 스케일도 필요",IF(AND($K21<>"",ISNA(MATCH($K21,$D$3:$D$170,0))),"선행스킬1 없음",IF(AND($L21<>"",ISNA(MATCH($L21,$D$3:$D$170,0))),"선행스킬2 없음",IF(AND($N21<>"",ISNA(MATCH($N21,$D$3:$D$170,0))),"타계열선행 없음","OK"))))))))) -> OK | T21: 5H-A | U21: 5도 쉬고 내려오기 | V21: 흉성(여자) | X21: 20 | Y21: 오픈허밍 마아~
A22: 저음 | B22: 5 | C22: 4 | D22: L5-4 | H22: =IF($F22="","",IF($G22="",IFERROR(INDEX(참조_스케일목록!$B:$B,MATCH($F22,참조_스케일목록!$A:$A,0))&" ("&INDEX(참조_스케일목록!$C:$C,MATCH($F22,참조_스케일목록!$A:$A,0))&")","※없는 ID"),"여 "&IFERROR(INDEX(참조_스케일목록!$B:$B,MATCH($F22,참조_스케일목록!$A:$A,0))&" ("&INDEX(참조_스케일목록!$C:$C,MATCH($F22,참조_스케일목록!$A:$A,0))&")","※없는 ID")&" / 남 "&IFERROR(INDEX(참조_스케일목록!$B:$B,MATCH($G22,참조_스케일목록!$A:$A,0))&" ("&INDEX(참조_스케일목록!$C:$C,MATCH($G22,참조_스케일목록!$A:$A,0))&")","※없는 ID"))) | P22: 준비중 | R22: =IF($A22="","",IF(AND($C22<>"",OR($C22<1,$C22>5,MOD($C22*2,1)<>0)),"자리는 1~5 (0.5단위)",IF(COUNTIFS($A$3:$A$170,$A22,$B$3:$B$170,$B22,$C$3:$C$170,$C22)>1,"같은 자리 중복",IF($D22="","스킬ID 비었음",IF(COUNTIF($D$3:$D$170,$D22)>1,"스킬ID 중복",IF(AND($G22<>"",$F22=""),"여 스케일도 필요",IF(AND($K22<>"",ISNA(MATCH($K22,$D$3:$D$170,0))),"선행스킬1 없음",IF(AND($L22<>"",ISNA(MATCH($L22,$D$3:$D$170,0))),"선행스킬2 없음",IF(AND($N22<>"",ISNA(MATCH($N22,$D$3:$D$170,0))),"타계열선행 없음","OK"))))))))) -> OK | T22: 5H-I | U22: 5도 쉬고 내려오기 | V22: 흉성(남자) | X22: 21 | Y22: 소울음소리
A23: 저음 | B23: 5 | C23: 5 | D23: L5-5 | E23: 강한 아(뒤) | F23: 3D-A | G23: 3D-B | H23: =IF($F23="","",IF($G23="",IFERROR(INDEX(참조_스케일목록!$B:$B,MATCH($F23,참조_스케일목록!$A:$A,0))&" ("&INDEX(참조_스케일목록!$C:$C,MATCH($F23,참조_스케일목록!$A:$A,0))&")","※없는 ID"),"여 "&IFERROR(INDEX(참조_스케일목록!$B:$B,MATCH($F23,참조_스케일목록!$A:$A,0))&" ("&INDEX(참조_스케일목록!$C:$C,MATCH($F23,참조_스케일목록!$A:$A,0))&")","※없는 ID")&" / 남 "&IFERROR(INDEX(참조_스케일목록!$B:$B,MATCH($G23,참조_스케일목록!$A:$A,0))&" ("&INDEX(참조_스케일목록!$C:$C,MATCH($G23,참조_스케일목록!$A:$A,0))&")","※없는 ID"))) -> 여 3도 스케일 (흉성(여자)) / 남 3도 스케일 (흉성(남)) | I23: 1 | J23: 7 | P23: 준비중 | R23: =IF($A23="","",IF(AND($C23<>"",OR($C23<1,$C23>5,MOD($C23*2,1)<>0)),"자리는 1~5 (0.5단위)",IF(COUNTIFS($A$3:$A$170,$A23,$B$3:$B$170,$B23,$C$3:$C$170,$C23)>1,"같은 자리 중복",IF($D23="","스킬ID 비었음",IF(COUNTIF($D$3:$D$170,$D23)>1,"스킬ID 중복",IF(AND($G23<>"",$F23=""),"여 스케일도 필요",IF(AND($K23<>"",ISNA(MATCH($K23,$D$3:$D$170,0))),"선행스킬1 없음",IF(AND($L23<>"",ISNA(MATCH($L23,$D$3:$D$170,0))),"선행스킬2 없음",IF(AND($N23<>"",ISNA(MATCH($N23,$D$3:$D$170,0))),"타계열선행 없음","OK"))))))))) -> OK | T23: 5H-E | U23: 5도 쉬고 내려오기 | V23: 흉성~낮은두성 | X23: 22 | Y23: 우~우~우~
A24: 저음 | B24: 6 | C24: 1 | D24: L6-1 | E24: 우 | F24: 3D-A | G24: 3D-B | H24: =IF($F24="","",IF($G24="",IFERROR(INDEX(참조_스케일목록!$B:$B,MATCH($F24,참조_스케일목록!$A:$A,0))&" ("&INDEX(참조_스케일목록!$C:$C,MATCH($F24,참조_스케일목록!$A:$A,0))&")","※없는 ID"),"여 "&IFERROR(INDEX(참조_스케일목록!$B:$B,MATCH($F24,참조_스케일목록!$A:$A,0))&" ("&INDEX(참조_스케일목록!$C:$C,MATCH($F24,참조_스케일목록!$A:$A,0))&")","※없는 ID")&" / 남 "&IFERROR(INDEX(참조_스케일목록!$B:$B,MATCH($G24,참조_스케일목록!$A:$A,0))&" ("&INDEX(참조_스케일목록!$C:$C,MATCH($G24,참조_스케일목록!$A:$A,0))&")","※없는 ID"))) -> 여 3도 스케일 (흉성(여자)) / 남 3도 스케일 (흉성(남)) | I24: 1 | J24: 7 | P24: 준비중 | R24: =IF($A24="","",IF(AND($C24<>"",OR($C24<1,$C24>5,MOD($C24*2,1)<>0)),"자리는 1~5 (0.5단위)",IF(COUNTIFS($A$3:$A$170,$A24,$B$3:$B$170,$B24,$C$3:$C$170,$C24)>1,"같은 자리 중복",IF($D24="","스킬ID 비었음",IF(COUNTIF($D$3:$D$170,$D24)>1,"스킬ID 중복",IF(AND($G24<>"",$F24=""),"여 스케일도 필요",IF(AND($K24<>"",ISNA(MATCH($K24,$D$3:$D$170,0))),"선행스킬1 없음",IF(AND($L24<>"",ISNA(MATCH($L24,$D$3:$D$170,0))),"선행스킬2 없음",IF(AND($N24<>"",ISNA(MATCH($N24,$D$3:$D$170,0))),"타계열선행 없음","OK"))))))))) -> OK | T24: 5H-F | U24: 5도 쉬고 내려오기 | V24: 흉성~높은두성 | X24: 23 | Y24: 강한 우~우~우~
A25: 저음 | B25: 6 | C25: 2 | D25: L6-2 | P25: 준비중 | R25: =IF($A25="","",IF(AND($C25<>"",OR($C25<1,$C25>5,MOD($C25*2,1)<>0)),"자리는 1~5 (0.5단위)",IF(COUNTIFS($A$3:$A$170,$A25,$B$3:$B$170,$B25,$C$3:$C$170,$C25)>1,"같은 자리 중복",IF($D25="","스킬ID 비었음",IF(COUNTIF($D$3:$D$170,$D25)>1,"스킬ID 중복",IF(AND($G25<>"",$F25=""),"여 스케일도 필요",IF(AND($K25<>"",ISNA(MATCH($K25,$D$3:$D$170,0))),"선행스킬1 없음",IF(AND($L25<>"",ISNA(MATCH($L25,$D$3:$D$170,0))),"선행스킬2 없음",IF(AND($N25<>"",ISNA(MATCH($N25,$D$3:$D$170,0))),"타계열선행 없음","OK"))))))))) -> OK | T25: 5H-G | U25: 5도 쉬고 내려오기 | V25: 중성~낮은중성 | X25: 24 | Y25: 호흡 섞은 우 소리내기
A26: 저음 | B26: 6 | C26: 3 | D26: L6-3 | H26: =IF($F26="","",IF($G26="",IFERROR(INDEX(참조_스케일목록!$B:$B,MATCH($F26,참조_스케일목록!$A:$A,0))&" ("&INDEX(참조_스케일목록!$C:$C,MATCH($F26,참조_스케일목록!$A:$A,0))&")","※없는 ID"),"여 "&IFERROR(INDEX(참조_스케일목록!$B:$B,MATCH($F26,참조_스케일목록!$A:$A,0))&" ("&INDEX(참조_스케일목록!$C:$C,MATCH($F26,참조_스케일목록!$A:$A,0))&")","※없는 ID")&" / 남 "&IFERROR(INDEX(참조_스케일목록!$B:$B,MATCH($G26,참조_스케일목록!$A:$A,0))&" ("&INDEX(참조_스케일목록!$C:$C,MATCH($G26,참조_스케일목록!$A:$A,0))&")","※없는 ID"))) | P26: 준비중 | R26: =IF($A26="","",IF(AND($C26<>"",OR($C26<1,$C26>5,MOD($C26*2,1)<>0)),"자리는 1~5 (0.5단위)",IF(COUNTIFS($A$3:$A$170,$A26,$B$3:$B$170,$B26,$C$3:$C$170,$C26)>1,"같은 자리 중복",IF($D26="","스킬ID 비었음",IF(COUNTIF($D$3:$D$170,$D26)>1,"스킬ID 중복",IF(AND($G26<>"",$F26=""),"여 스케일도 필요",IF(AND($K26<>"",ISNA(MATCH($K26,$D$3:$D$170,0))),"선행스킬1 없음",IF(AND($L26<>"",ISNA(MATCH($L26,$D$3:$D$170,0))),"선행스킬2 없음",IF(AND($N26<>"",ISNA(MATCH($N26,$D$3:$D$170,0))),"타계열선행 없음","OK"))))))))) -> OK | T26: 5H-H | U26: 5도 쉬고 내려오기 | V26: 중성~높은중성 | X26: 25 | Y26: 가슴에 호흡 대기
A27: 저음 | B27: 6 | C27: 4 | D27: L6-4 | H27: =IF($F27="","",IF($G27="",IFERROR(INDEX(참조_스케일목록!$B:$B,MATCH($F27,참조_스케일목록!$A:$A,0))&" ("&INDEX(참조_스케일목록!$C:$C,MATCH($F27,참조_스케일목록!$A:$A,0))&")","※없는 ID"),"여 "&IFERROR(INDEX(참조_스케일목록!$B:$B,MATCH($F27,참조_스케일목록!$A:$A,0))&" ("&INDEX(참조_스케일목록!$C:$C,MATCH($F27,참조_스케일목록!$A:$A,0))&")","※없는 ID")&" / 남 "&IFERROR(INDEX(참조_스케일목록!$B:$B,MATCH($G27,참조_스케일목록!$A:$A,0))&" ("&INDEX(참조_스케일목록!$C:$C,MATCH($G27,참조_스케일목록!$A:$A,0))&")","※없는 ID"))) | P27: 준비중 | R27: =IF($A27="","",IF(AND($C27<>"",OR($C27<1,$C27>5,MOD($C27*2,1)<>0)),"자리는 1~5 (0.5단위)",IF(COUNTIFS($A$3:$A$170,$A27,$B$3:$B$170,$B27,$C$3:$C$170,$C27)>1,"같은 자리 중복",IF($D27="","스킬ID 비었음",IF(COUNTIF($D$3:$D$170,$D27)>1,"스킬ID 중복",IF(AND($G27<>"",$F27=""),"여 스케일도 필요",IF(AND($K27<>"",ISNA(MATCH($K27,$D$3:$D$170,0))),"선행스킬1 없음",IF(AND($L27<>"",ISNA(MATCH($L27,$D$3:$D$170,0))),"선행스킬2 없음",IF(AND($N27<>"",ISNA(MATCH($N27,$D$3:$D$170,0))),"타계열선행 없음","OK"))))))))) -> OK | T27: 5H-B | U27: 5도 쉬고 내려오기 | V27: 중성~낮은두성 | X27: 26 | Y27: 강한 성대음 만들기 (흉성)
A28: 저음 | B28: 6 | C28: 5 | D28: L6-5 | E28: 아 | F28: 3D-A | G28: 3D-B | H28: =IF($F28="","",IF($G28="",IFERROR(INDEX(참조_스케일목록!$B:$B,MATCH($F28,참조_스케일목록!$A:$A,0))&" ("&INDEX(참조_스케일목록!$C:$C,MATCH($F28,참조_스케일목록!$A:$A,0))&")","※없는 ID"),"여 "&IFERROR(INDEX(참조_스케일목록!$B:$B,MATCH($F28,참조_스케일목록!$A:$A,0))&" ("&INDEX(참조_스케일목록!$C:$C,MATCH($F28,참조_스케일목록!$A:$A,0))&")","※없는 ID")&" / 남 "&IFERROR(INDEX(참조_스케일목록!$B:$B,MATCH($G28,참조_스케일목록!$A:$A,0))&" ("&INDEX(참조_스케일목록!$C:$C,MATCH($G28,참조_스케일목록!$A:$A,0))&")","※없는 ID"))) -> 여 3도 스케일 (흉성(여자)) / 남 3도 스케일 (흉성(남)) | I28: 1 | J28: 7 | P28: 준비중 | R28: =IF($A28="","",IF(AND($C28<>"",OR($C28<1,$C28>5,MOD($C28*2,1)<>0)),"자리는 1~5 (0.5단위)",IF(COUNTIFS($A$3:$A$170,$A28,$B$3:$B$170,$B28,$C$3:$C$170,$C28)>1,"같은 자리 중복",IF($D28="","스킬ID 비었음",IF(COUNTIF($D$3:$D$170,$D28)>1,"스킬ID 중복",IF(AND($G28<>"",$F28=""),"여 스케일도 필요",IF(AND($K28<>"",ISNA(MATCH($K28,$D$3:$D$170,0))),"선행스킬1 없음",IF(AND($L28<>"",ISNA(MATCH($L28,$D$3:$D$170,0))),"선행스킬2 없음",IF(AND($N28<>"",ISNA(MATCH($N28,$D$3:$D$170,0))),"타계열선행 없음","OK"))))))))) -> OK | T28: 5H-C | U28: 5도 쉬고 내려오기 | V28: 중성~높은두성 | X28: 27 | Y28: 강한 성대음 만들기 (중성)
A29: 중음 | B29: 1 | C29: 1 | D29: M1-1 | H29: =IF($F29="","",IF($G29="",IFERROR(INDEX(참조_스케일목록!$B:$B,MATCH($F29,참조_스케일목록!$A:$A,0))&" ("&INDEX(참조_스케일목록!$C:$C,MATCH($F29,참조_스케일목록!$A:$A,0))&")","※없는 ID"),"여 "&IFERROR(INDEX(참조_스케일목록!$B:$B,MATCH($F29,참조_스케일목록!$A:$A,0))&" ("&INDEX(참조_스케일목록!$C:$C,MATCH($F29,참조_스케일목록!$A:$A,0))&")","※없는 ID")&" / 남 "&IFERROR(INDEX(참조_스케일목록!$B:$B,MATCH($G29,참조_스케일목록!$A:$A,0))&" ("&INDEX(참조_스케일목록!$C:$C,MATCH($G29,참조_스케일목록!$A:$A,0))&")","※없는 ID"))) | P29: 공개 | R29: =IF($A29="","",IF(AND($C29<>"",OR($C29<1,$C29>5,MOD($C29*2,1)<>0)),"자리는 1~5 (0.5단위)",IF(COUNTIFS($A$3:$A$170,$A29,$B$3:$B$170,$B29,$C$3:$C$170,$C29)>1,"같은 자리 중복",IF($D29="","스킬ID 비었음",IF(COUNTIF($D$3:$D$170,$D29)>1,"스킬ID 중복",IF(AND($G29<>"",$F29=""),"여 스케일도 필요",IF(AND($K29<>"",ISNA(MATCH($K29,$D$3:$D$170,0))),"선행스킬1 없음",IF(AND($L29<>"",ISNA(MATCH($L29,$D$3:$D$170,0))),"선행스킬2 없음",IF(AND($N29<>"",ISNA(MATCH($N29,$D$3:$D$170,0))),"타계열선행 없음","OK"))))))))) -> OK | T29: 5H-D | U29: 5도 쉬고 내려오기 | V29: 중성~휘슬
A30: 중음 | B30: 1 | C30: 2 | D30: M1-2 | H30: =IF($F30="","",IF($G30="",IFERROR(INDEX(참조_스케일목록!$B:$B,MATCH($F30,참조_스케일목록!$A:$A,0))&" ("&INDEX(참조_스케일목록!$C:$C,MATCH($F30,참조_스케일목록!$A:$A,0))&")","※없는 ID"),"여 "&IFERROR(INDEX(참조_스케일목록!$B:$B,MATCH($F30,참조_스케일목록!$A:$A,0))&" ("&INDEX(참조_스케일목록!$C:$C,MATCH($F30,참조_스케일목록!$A:$A,0))&")","※없는 ID")&" / 남 "&IFERROR(INDEX(참조_스케일목록!$B:$B,MATCH($G30,참조_스케일목록!$A:$A,0))&" ("&INDEX(참조_스케일목록!$C:$C,MATCH($G30,참조_스케일목록!$A:$A,0))&")","※없는 ID"))) | P30: 공개 | R30: =IF($A30="","",IF(AND($C30<>"",OR($C30<1,$C30>5,MOD($C30*2,1)<>0)),"자리는 1~5 (0.5단위)",IF(COUNTIFS($A$3:$A$170,$A30,$B$3:$B$170,$B30,$C$3:$C$170,$C30)>1,"같은 자리 중복",IF($D30="","스킬ID 비었음",IF(COUNTIF($D$3:$D$170,$D30)>1,"스킬ID 중복",IF(AND($G30<>"",$F30=""),"여 스케일도 필요",IF(AND($K30<>"",ISNA(MATCH($K30,$D$3:$D$170,0))),"선행스킬1 없음",IF(AND($L30<>"",ISNA(MATCH($L30,$D$3:$D$170,0))),"선행스킬2 없음",IF(AND($N30<>"",ISNA(MATCH($N30,$D$3:$D$170,0))),"타계열선행 없음","OK"))))))))) -> OK | T30: 9D-A | U30: 9도 스케일 | V30: 흉성~낮은두성
A31: 중음 | B31: 1 | C31: 3 | D31: M1-3 | E31: 립트릴 | F31: 5D-E | G31: 5D-F | H31: =IF($F31="","",IF($G31="",IFERROR(INDEX(참조_스케일목록!$B:$B,MATCH($F31,참조_스케일목록!$A:$A,0))&" ("&INDEX(참조_스케일목록!$C:$C,MATCH($F31,참조_스케일목록!$A:$A,0))&")","※없는 ID"),"여 "&IFERROR(INDEX(참조_스케일목록!$B:$B,MATCH($F31,참조_스케일목록!$A:$A,0))&" ("&INDEX(참조_스케일목록!$C:$C,MATCH($F31,참조_스케일목록!$A:$A,0))&")","※없는 ID")&" / 남 "&IFERROR(INDEX(참조_스케일목록!$B:$B,MATCH($G31,참조_스케일목록!$A:$A,0))&" ("&INDEX(참조_스케일목록!$C:$C,MATCH($G31,참조_스케일목록!$A:$A,0))&")","※없는 ID"))) -> 여 5도 스케일 (중성~낮은중성) / 남 5도 스케일 (중성~높은중성) | I31: 1 | J31: 7 | O31: 13 | P31: 공개 | R31: =IF($A31="","",IF(AND($C31<>"",OR($C31<1,$C31>5,MOD($C31*2,1)<>0)),"자리는 1~5 (0.5단위)",IF(COUNTIFS($A$3:$A$170,$A31,$B$3:$B$170,$B31,$C$3:$C$170,$C31)>1,"같은 자리 중복",IF($D31="","스킬ID 비었음",IF(COUNTIF($D$3:$D$170,$D31)>1,"스킬ID 중복",IF(AND($G31<>"",$F31=""),"여 스케일도 필요",IF(AND($K31<>"",ISNA(MATCH($K31,$D$3:$D$170,0))),"선행스킬1 없음",IF(AND($L31<>"",ISNA(MATCH($L31,$D$3:$D$170,0))),"선행스킬2 없음",IF(AND($N31<>"",ISNA(MATCH($N31,$D$3:$D$170,0))),"타계열선행 없음","OK"))))))))) -> OK | T31: 9D-B | U31: 9도 스케일 | V31: 흉성~높은두성 | X31: 29 | Y31: 강한 우(뒤)
A32: 중음 | B32: 1 | C32: 4 | D32: M1-4 | H32: =IF($F32="","",IF($G32="",IFERROR(INDEX(참조_스케일목록!$B:$B,MATCH($F32,참조_스케일목록!$A:$A,0))&" ("&INDEX(참조_스케일목록!$C:$C,MATCH($F32,참조_스케일목록!$A:$A,0))&")","※없는 ID"),"여 "&IFERROR(INDEX(참조_스케일목록!$B:$B,MATCH($F32,참조_스케일목록!$A:$A,0))&" ("&INDEX(참조_스케일목록!$C:$C,MATCH($F32,참조_스케일목록!$A:$A,0))&")","※없는 ID")&" / 남 "&IFERROR(INDEX(참조_스케일목록!$B:$B,MATCH($G32,참조_스케일목록!$A:$A,0))&" ("&INDEX(참조_스케일목록!$C:$C,MATCH($G32,참조_스케일목록!$A:$A,0))&")","※없는 ID"))) | P32: 공개 | R32: =IF($A32="","",IF(AND($C32<>"",OR($C32<1,$C32>5,MOD($C32*2,1)<>0)),"자리는 1~5 (0.5단위)",IF(COUNTIFS($A$3:$A$170,$A32,$B$3:$B$170,$B32,$C$3:$C$170,$C32)>1,"같은 자리 중복",IF($D32="","스킬ID 비었음",IF(COUNTIF($D$3:$D$170,$D32)>1,"스킬ID 중복",IF(AND($G32<>"",$F32=""),"여 스케일도 필요",IF(AND($K32<>"",ISNA(MATCH($K32,$D$3:$D$170,0))),"선행스킬1 없음",IF(AND($L32<>"",ISNA(MATCH($L32,$D$3:$D$170,0))),"선행스킬2 없음",IF(AND($N32<>"",ISNA(MATCH($N32,$D$3:$D$170,0))),"타계열선행 없음","OK"))))))))) -> OK | T32: 9D-C | U32: 9도 스케일 | V32: 흉성~휘슬
A33: 중음 | B33: 1 | C33: 5 | D33: M1-5 | H33: =IF($F33="","",IF($G33="",IFERROR(INDEX(참조_스케일목록!$B:$B,MATCH($F33,참조_스케일목록!$A:$A,0))&" ("&INDEX(참조_스케일목록!$C:$C,MATCH($F33,참조_스케일목록!$A:$A,0))&")","※없는 ID"),"여 "&IFERROR(INDEX(참조_스케일목록!$B:$B,MATCH($F33,참조_스케일목록!$A:$A,0))&" ("&INDEX(참조_스케일목록!$C:$C,MATCH($F33,참조_스케일목록!$A:$A,0))&")","※없는 ID")&" / 남 "&IFERROR(INDEX(참조_스케일목록!$B:$B,MATCH($G33,참조_스케일목록!$A:$A,0))&" ("&INDEX(참조_스케일목록!$C:$C,MATCH($G33,참조_스케일목록!$A:$A,0))&")","※없는 ID"))) | P33: 공개 | R33: =IF($A33="","",IF(AND($C33<>"",OR($C33<1,$C33>5,MOD($C33*2,1)<>0)),"자리는 1~5 (0.5단위)",IF(COUNTIFS($A$3:$A$170,$A33,$B$3:$B$170,$B33,$C$3:$C$170,$C33)>1,"같은 자리 중복",IF($D33="","스킬ID 비었음",IF(COUNTIF($D$3:$D$170,$D33)>1,"스킬ID 중복",IF(AND($G33<>"",$F33=""),"여 스케일도 필요",IF(AND($K33<>"",ISNA(MATCH($K33,$D$3:$D$170,0))),"선행스킬1 없음",IF(AND($L33<>"",ISNA(MATCH($L33,$D$3:$D$170,0))),"선행스킬2 없음",IF(AND($N33<>"",ISNA(MATCH($N33,$D$3:$D$170,0))),"타계열선행 없음","OK"))))))))) -> OK | T33: 9H-A | U33: 9도 쉬고 내려오기 | V33: 흉성~낮은두성
A34: 중음 | B34: 2 | C34: 1 | D34: M2-1 | E34: 허밍 | H34: =IF($F34="","",IF($G34="",IFERROR(INDEX(참조_스케일목록!$B:$B,MATCH($F34,참조_스케일목록!$A:$A,0))&" ("&INDEX(참조_스케일목록!$C:$C,MATCH($F34,참조_스케일목록!$A:$A,0))&")","※없는 ID"),"여 "&IFERROR(INDEX(참조_스케일목록!$B:$B,MATCH($F34,참조_스케일목록!$A:$A,0))&" ("&INDEX(참조_스케일목록!$C:$C,MATCH($F34,참조_스케일목록!$A:$A,0))&")","※없는 ID")&" / 남 "&IFERROR(INDEX(참조_스케일목록!$B:$B,MATCH($G34,참조_스케일목록!$A:$A,0))&" ("&INDEX(참조_스케일목록!$C:$C,MATCH($G34,참조_스케일목록!$A:$A,0))&")","※없는 ID"))) | I34: 1 | J34: 7 | K34: M1-3 | P34: 공개 | R34: =IF($A34="","",IF(AND($C34<>"",OR($C34<1,$C34>5,MOD($C34*2,1)<>0)),"자리는 1~5 (0.5단위)",IF(COUNTIFS($A$3:$A$170,$A34,$B$3:$B$170,$B34,$C$3:$C$170,$C34)>1,"같은 자리 중복",IF($D34="","스킬ID 비었음",IF(COUNTIF($D$3:$D$170,$D34)>1,"스킬ID 중복",IF(AND($G34<>"",$F34=""),"여 스케일도 필요",IF(AND($K34<>"",ISNA(MATCH($K34,$D$3:$D$170,0))),"선행스킬1 없음",IF(AND($L34<>"",ISNA(MATCH($L34,$D$3:$D$170,0))),"선행스킬2 없음",IF(AND($N34<>"",ISNA(MATCH($N34,$D$3:$D$170,0))),"타계열선행 없음","OK"))))))))) -> OK | T34: 9H-B | U34: 9도 쉬고 내려오기 | V34: 흉성~높은두성 | X34: 30 | Y34: 강한 우
A35: 중음 | B35: 2 | C35: 2 | D35: M2-2 | H35: =IF($F35="","",IF($G35="",IFERROR(INDEX(참조_스케일목록!$B:$B,MATCH($F35,참조_스케일목록!$A:$A,0))&" ("&INDEX(참조_스케일목록!$C:$C,MATCH($F35,참조_스케일목록!$A:$A,0))&")","※없는 ID"),"여 "&IFERROR(INDEX(참조_스케일목록!$B:$B,MATCH($F35,참조_스케일목록!$A:$A,0))&" ("&INDEX(참조_스케일목록!$C:$C,MATCH($F35,참조_스케일목록!$A:$A,0))&")","※없는 ID")&" / 남 "&IFERROR(INDEX(참조_스케일목록!$B:$B,MATCH($G35,참조_스케일목록!$A:$A,0))&" ("&INDEX(참조_스케일목록!$C:$C,MATCH($G35,참조_스케일목록!$A:$A,0))&")","※없는 ID"))) | P35: 공개 | R35: =IF($A35="","",IF(AND($C35<>"",OR($C35<1,$C35>5,MOD($C35*2,1)<>0)),"자리는 1~5 (0.5단위)",IF(COUNTIFS($A$3:$A$170,$A35,$B$3:$B$170,$B35,$C$3:$C$170,$C35)>1,"같은 자리 중복",IF($D35="","스킬ID 비었음",IF(COUNTIF($D$3:$D$170,$D35)>1,"스킬ID 중복",IF(AND($G35<>"",$F35=""),"여 스케일도 필요",IF(AND($K35<>"",ISNA(MATCH($K35,$D$3:$D$170,0))),"선행스킬1 없음",IF(AND($L35<>"",ISNA(MATCH($L35,$D$3:$D$170,0))),"선행스킬2 없음",IF(AND($N35<>"",ISNA(MATCH($N35,$D$3:$D$170,0))),"타계열선행 없음","OK"))))))))) -> OK | T35: 9H-C | U35: 9도 쉬고 내려오기 | V35: 흉성~휘슬
A36: 중음 | B36: 2 | C36: 3 | D36: M2-3 | E36: 립트릴 | F36: 5D-B | H36: =IF($F36="","",IF($G36="",IFERROR(INDEX(참조_스케일목록!$B:$B,MATCH($F36,참조_스케일목록!$A:$A,0))&" ("&INDEX(참조_스케일목록!$C:$C,MATCH($F36,참조_스케일목록!$A:$A,0))&")","※없는 ID"),"여 "&IFERROR(INDEX(참조_스케일목록!$B:$B,MATCH($F36,참조_스케일목록!$A:$A,0))&" ("&INDEX(참조_스케일목록!$C:$C,MATCH($F36,참조_스케일목록!$A:$A,0))&")","※없는 ID")&" / 남 "&IFERROR(INDEX(참조_스케일목록!$B:$B,MATCH($G36,참조_스케일목록!$A:$A,0))&" ("&INDEX(참조_스케일목록!$C:$C,MATCH($G36,참조_스케일목록!$A:$A,0))&")","※없는 ID"))) -> 5도 스케일 (흉성~낮은두성) | I36: 1 | J36: 7 | P36: 공개 | R36: =IF($A36="","",IF(AND($C36<>"",OR($C36<1,$C36>5,MOD($C36*2,1)<>0)),"자리는 1~5 (0.5단위)",IF(COUNTIFS($A$3:$A$170,$A36,$B$3:$B$170,$B36,$C$3:$C$170,$C36)>1,"같은 자리 중복",IF($D36="","스킬ID 비었음",IF(COUNTIF($D$3:$D$170,$D36)>1,"스킬ID 중복",IF(AND($G36<>"",$F36=""),"여 스케일도 필요",IF(AND($K36<>"",ISNA(MATCH($K36,$D$3:$D$170,0))),"선행스킬1 없음",IF(AND($L36<>"",ISNA(MATCH($L36,$D$3:$D$170,0))),"선행스킬2 없음",IF(AND($N36<>"",ISNA(MATCH($N36,$D$3:$D$170,0))),"타계열선행 없음","OK"))))))))) -> OK | T36: 5DN-A | U36: 5도 하향 스케일 | V36: 흉성(여자) | X36: 31 | Y36: 강한 후우
A37: 중음 | B37: 2 | C37: 4 | D37: M2-4 | H37: =IF($F37="","",IF($G37="",IFERROR(INDEX(참조_스케일목록!$B:$B,MATCH($F37,참조_스케일목록!$A:$A,0))&" ("&INDEX(참조_스케일목록!$C:$C,MATCH($F37,참조_스케일목록!$A:$A,0))&")","※없는 ID"),"여 "&IFERROR(INDEX(참조_스케일목록!$B:$B,MATCH($F37,참조_스케일목록!$A:$A,0))&" ("&INDEX(참조_스케일목록!$C:$C,MATCH($F37,참조_스케일목록!$A:$A,0))&")","※없는 ID")&" / 남 "&IFERROR(INDEX(참조_스케일목록!$B:$B,MATCH($G37,참조_스케일목록!$A:$A,0))&" ("&INDEX(참조_스케일목록!$C:$C,MATCH($G37,참조_스케일목록!$A:$A,0))&")","※없는 ID"))) | P37: 공개 | R37: =IF($A37="","",IF(AND($C37<>"",OR($C37<1,$C37>5,MOD($C37*2,1)<>0)),"자리는 1~5 (0.5단위)",IF(COUNTIFS($A$3:$A$170,$A37,$B$3:$B$170,$B37,$C$3:$C$170,$C37)>1,"같은 자리 중복",IF($D37="","스킬ID 비었음",IF(COUNTIF($D$3:$D$170,$D37)>1,"스킬ID 중복",IF(AND($G37<>"",$F37=""),"여 스케일도 필요",IF(AND($K37<>"",ISNA(MATCH($K37,$D$3:$D$170,0))),"선행스킬1 없음",IF(AND($L37<>"",ISNA(MATCH($L37,$D$3:$D$170,0))),"선행스킬2 없음",IF(AND($N37<>"",ISNA(MATCH($N37,$D$3:$D$170,0))),"타계열선행 없음","OK"))))))))) -> OK | T37: 5DN-H | U37: 5도 하향 스케일 | V37: 흉성(남자)
A38: 중음 | B38: 2 | C38: 5 | D38: M2-5 | E38: Z 소리내기 | F38: 3D-E | G38: 3D-F | H38: =IF($F38="","",IF($G38="",IFERROR(INDEX(참조_스케일목록!$B:$B,MATCH($F38,참조_스케일목록!$A:$A,0))&" ("&INDEX(참조_스케일목록!$C:$C,MATCH($F38,참조_스케일목록!$A:$A,0))&")","※없는 ID"),"여 "&IFERROR(INDEX(참조_스케일목록!$B:$B,MATCH($F38,참조_스케일목록!$A:$A,0))&" ("&INDEX(참조_스케일목록!$C:$C,MATCH($F38,참조_스케일목록!$A:$A,0))&")","※없는 ID")&" / 남 "&IFERROR(INDEX(참조_스케일목록!$B:$B,MATCH($G38,참조_스케일목록!$A:$A,0))&" ("&INDEX(참조_스케일목록!$C:$C,MATCH($G38,참조_스케일목록!$A:$A,0))&")","※없는 ID"))) -> 여 3도 스케일 (낮은중성) / 남 3도 스케일 (높은중성) | I38: 1 | J38: 7 | K38: M1-3 | P38: 공개 | R38: =IF($A38="","",IF(AND($C38<>"",OR($C38<1,$C38>5,MOD($C38*2,1)<>0)),"자리는 1~5 (0.5단위)",IF(COUNTIFS($A$3:$A$170,$A38,$B$3:$B$170,$B38,$C$3:$C$170,$C38)>1,"같은 자리 중복",IF($D38="","스킬ID 비었음",IF(COUNTIF($D$3:$D$170,$D38)>1,"스킬ID 중복",IF(AND($G38<>"",$F38=""),"여 스케일도 필요",IF(AND($K38<>"",ISNA(MATCH($K38,$D$3:$D$170,0))),"선행스킬1 없음",IF(AND($L38<>"",ISNA(MATCH($L38,$D$3:$D$170,0))),"선행스킬2 없음",IF(AND($N38<>"",ISNA(MATCH($N38,$D$3:$D$170,0))),"타계열선행 없음","OK"))))))))) -> OK | T38: 5DN-B | U38: 5도 하향 스케일 | V38: 흉성~높은두성
A39: 중음 | B39: 3 | C39: 1 | D39: M3-1 | E39: 오픈 허밍 1번 | F39: 5H-G | G39: 5H-H | H39: =IF($F39="","",IF($G39="",IFERROR(INDEX(참조_스케일목록!$B:$B,MATCH($F39,참조_스케일목록!$A:$A,0))&" ("&INDEX(참조_스케일목록!$C:$C,MATCH($F39,참조_스케일목록!$A:$A,0))&")","※없는 ID"),"여 "&IFERROR(INDEX(참조_스케일목록!$B:$B,MATCH($F39,참조_스케일목록!$A:$A,0))&" ("&INDEX(참조_스케일목록!$C:$C,MATCH($F39,참조_스케일목록!$A:$A,0))&")","※없는 ID")&" / 남 "&IFERROR(INDEX(참조_스케일목록!$B:$B,MATCH($G39,참조_스케일목록!$A:$A,0))&" ("&INDEX(참조_스케일목록!$C:$C,MATCH($G39,참조_스케일목록!$A:$A,0))&")","※없는 ID"))) -> 여 5도 쉬고 내려오기 (중성~낮은중성) / 남 5도 쉬고 내려오기 (중성~높은중성) | I39: 1 | J39: 7 | P39: 준비중 | R39: =IF($A39="","",IF(AND($C39<>"",OR($C39<1,$C39>5,MOD($C39*2,1)<>0)),"자리는 1~5 (0.5단위)",IF(COUNTIFS($A$3:$A$170,$A39,$B$3:$B$170,$B39,$C$3:$C$170,$C39)>1,"같은 자리 중복",IF($D39="","스킬ID 비었음",IF(COUNTIF($D$3:$D$170,$D39)>1,"스킬ID 중복",IF(AND($G39<>"",$F39=""),"여 스케일도 필요",IF(AND($K39<>"",ISNA(MATCH($K39,$D$3:$D$170,0))),"선행스킬1 없음",IF(AND($L39<>"",ISNA(MATCH($L39,$D$3:$D$170,0))),"선행스킬2 없음",IF(AND($N39<>"",ISNA(MATCH($N39,$D$3:$D$170,0))),"타계열선행 없음","OK"))))))))) -> OK | T39: 5DN-F | U39: 5도 하향 스케일 | V39: 중성~낮은중성
A40: 중음 | B40: 3 | C40: 2 | D40: M3-2 | H40: =IF($F40="","",IF($G40="",IFERROR(INDEX(참조_스케일목록!$B:$B,MATCH($F40,참조_스케일목록!$A:$A,0))&" ("&INDEX(참조_스케일목록!$C:$C,MATCH($F40,참조_스케일목록!$A:$A,0))&")","※없는 ID"),"여 "&IFERROR(INDEX(참조_스케일목록!$B:$B,MATCH($F40,참조_스케일목록!$A:$A,0))&" ("&INDEX(참조_스케일목록!$C:$C,MATCH($F40,참조_스케일목록!$A:$A,0))&")","※없는 ID")&" / 남 "&IFERROR(INDEX(참조_스케일목록!$B:$B,MATCH($G40,참조_스케일목록!$A:$A,0))&" ("&INDEX(참조_스케일목록!$C:$C,MATCH($G40,참조_스케일목록!$A:$A,0))&")","※없는 ID"))) | P40: 준비중 | R40: =IF($A40="","",IF(AND($C40<>"",OR($C40<1,$C40>5,MOD($C40*2,1)<>0)),"자리는 1~5 (0.5단위)",IF(COUNTIFS($A$3:$A$170,$A40,$B$3:$B$170,$B40,$C$3:$C$170,$C40)>1,"같은 자리 중복",IF($D40="","스킬ID 비었음",IF(COUNTIF($D$3:$D$170,$D40)>1,"스킬ID 중복",IF(AND($G40<>"",$F40=""),"여 스케일도 필요",IF(AND($K40<>"",ISNA(MATCH($K40,$D$3:$D$170,0))),"선행스킬1 없음",IF(AND($L40<>"",ISNA(MATCH($L40,$D$3:$D$170,0))),"선행스킬2 없음",IF(AND($N40<>"",ISNA(MATCH($N40,$D$3:$D$170,0))),"타계열선행 없음","OK"))))))))) -> OK | T40: 5DN-G | U40: 5도 하향 스케일 | V40: 중성~높은중성 | X40: 32 | Y40: 아~아~아~
...

Sheet 계열정의
A1: 계열키 | B1: 계열이름 | C1: 색상 | D1: 호흡해금일차 | E1: 한줄소개 | F1: 키워드1 | G1: 키워드2 | H1: 키워드3 | I1: 내부메모
A2: low | B2: 저음 | C2: #2563eb | D2: 7 | E2: 울림의 바닥부터 넓히는 계열 | F2: 소리가 작다는 말을 들었을 때 | G2: 기초부터 탄탄히 하고 싶을 때 | H2: 목소리에 힘을 싣고 싶을 때 | I2: 흉성 계열. 가슴 울림과 낮은 음역 기반을 만드는 판.
A3: mid | B3: 중음 | C3: #0d9488 | D3: 7 | E3: 가장 많이 쓰는 음역, 가장 많이 티 나는 구간 | F3: 말하듯이 노래하고 싶을 때 | G3: 발라드 한 곡 제대로 부르고 싶을 때 | H3: 노래만 하면 목이 뻣뻣해질 때 | I3: 중성 계열. 립트릴·허밍 등 성구전환 준비 단계.
A4: high | B4: 고음 | C4: #7c3aed | D4: 10 | E4: 위로 가는 길을 뚫는 계열 | F4: 노래방 약속이 잡힌 금요일 | G4: 락이 그리울 때 | H4: 늘 후렴에서 막힐 때 | I4: 두성 계열. 호흡을 더 확보한 뒤 열리도록 늦게 해금.
A5: care | B5: 성대결절 케어 | C5: #16a34a | D5: 5 | E5: 지친 성대를 되돌리는 시간 | F5: 어제 좀 무리했다 싶을 때 | G5: 목이 자주 잠기는 편이라면 | H5: 쉬는 것도 훈련이니까 | I5: 성대결절 회복에 도움을 주는 훈련.
A7: ※ 한줄소개=계열 판 상단 표시 / 키워드='이럴 때 좋아요' 칩. 자유롭게 고치세요.

Sheet 참조_훈련목록
A1: 넘버 | B1: 훈련명
A2: 1 | B2: 가슴 소리 만들기
A3: 2 | B3: 발성훈련 셋팅
A4: 3 | B4: 흉복식호흡
A5: 4 | B5: 주먹쥐고 호흡
A6: 5 | B6: 호흡 저항 도구 훈련
A7: 6 | B7: 립트릴
A8: 7 | B8: 립트릴 1번
A9: 8 | B9: 립트릴 2번
A10: 9 | B10: 립트릴 3번
A11: 10 | B11: 립트릴 4번
A12: 11 | B12: S로 호흡 뱉기
A13: 12 | B13: S로 스타카토 호흡뱉기
... A44: 43 | B44: 후~ 내려오기

Sheet 참조_스케일목록
A1: 스케일ID | B1: 스케일명 | C1: 음역
A2: 3D-A | B2: 3도 스케일 | C2: 흉성(여자)
A3: 3D-B | B3: 3도 스케일 | C3: 흉성(남)
A4: 3D-C | B4: 3도 스케일 | C4: 흉성~낮은중성
A5: 3D-D | B5: 3도 스케일 | C5: 흉성~높은중성
A6: 3D-E | B6: 3도 스케일 | C6: 낮은중성
A7: 3D-F | B7: 3도 스케일 | C7: 높은중성
A8: 3D-G | B8: 3도 스케일 | C8: 흉성~낮은두성
A9: 3D-H | B9: 3도 스케일 | C9: 흉성~높은두성
A10: 3D-I | B10: 3도 스케일 | C10: 흉성(여자)
A11: 5D-A | B11: 5도 스케일 | C11: 흉성(여자)
A12: 5D-J | B12: 5도 스케일 | C12: 흉성(남자)
... A73: ARP-D | B73: 아르페지오 스케일 | C73: 흉성~높은두성

Sheet 훈련내용
A1: 훈련 스킬 카드 내용 — 호흡 훈련하기 카드와 같은 방식입니다. 스킬 하나에 카드를 여러 장 쓰려면 아래에 같은 스킬ID로 줄을 추가하세요.
A2: 스킬ID | B2: 스킬명 | C2: 계열 | D2: 카드번호 | E2: 본문 (카드에 표시될 글) | F2: [멘트만] (음성으로만 나갈 말) | G2: 미디어 (영상/사진 링크) | H2: BGM | I2: 메모
A3: L1-3 | B3: 소울음소리 | C3: 저음 | D3: 1
A4: L2-1 | B4: 우~우~우~ | C4: 저음 | D4: 1
A5: L2-2 | B5: 아~아~아~ | C5: 저음 | D5: 1
A6: L2-3 | B6: 립트릴 | C6: 저음 | D6: 1
A7: L2-4 | C7: 저음 | D7: 1 | I7: 훈련명 미정 (자리만 확보)
A8: L2-5 | C8: 저음 | D8: 1 | I8: 훈련명 미정 (자리만 확보)
A9: L3-1 | B9: 강한 우~우~우~ | C9: 저음 | D9: 1
A10: L3-2 | B10: 강한 아~아~아~ | C10: 저음 | D10: 1
A11: L3-3 | B11: 립트릴 | C11: 저음 | D11: 1
A12: L3-4 | C12: 저음 | D12: 1 | I12: 훈련명 미정 (자리만 확보)
A13: L3-5 | C13: 저음 | D13: 1 | I13: 훈련명 미정 (자리만 확보)
A14: L4-1 | B14: 강한 우(앞) | C14: 저음 | D14: 1
A15: L4-2 | B15: 강한 아(앞) | C15: 저음 | D15: 1
A16: L4-3 | C16: 저음 | D16: 1 | I16: 훈련명 미정 (자리만 확보)
A17: L4-4 | C17: 저음 | D17: 1 | I17: 훈련명 미정 (자리만 확보)
A18: L4-5 | C18: 저음 | D18: 1 | I18: 훈련명 미정 (자리만 확보)
A19: L5-1 | B19: 강한 우(뒤) | C19: 저음 | D19: 1
A20: L5-2 | B20: 강한 아(뒤) | C20: 저음 | D20: 1
A21: L5-3 | C21: 저음 | D21: 1 | I21: 훈련명 미정 (자리만 확보)
A22: L5-4 | C22: 저음 | D22: 1 | I22: 훈련명 미정 (자리만 확보)
A23: L5-5 | C23: 저음 | D23: 1 | I23: 훈련명 미정 (자리만 확보)
A24: L6-1 | B24: 우 | C24: 저음 | D24: 1
A25: L6-2 | B25: 아 | C25: 저음 | D25: 1
A26: L6-3 | C26: 저음 | D26: 1 | I26: 훈련명 미정 (자리만 확보)
A27: L6-4 | C27: 저음 | D27: 1 | I27: 훈련명 미정 (자리만 확보)
A28: L6-5 | C28: 저음 | D28: 1 | I28: 훈련명 미정 (자리만 확보)
A29: M1-1 | C29: 중음 | D29: 1 | I29: 훈련명 미정 (자리만 확보)
A30: H1-1 | C30: 중음 | D30: 1 | I30: 훈련명 미정 (자리만 확보)
A31: M1-2 | C31: 중음 | D31: 1 | I31: 훈련명 미정 (자리만 확보)
A32: H1-2 | C32: 중음 | D32: 1 | I32: 훈련명 미정 (자리만 확보)
A33: M1-3 | B33: 립트릴 | C33: 중음 | D33: 1
A34: M1-4 | C34: 중음 | D34: 1 | I34: 훈련명 미정 (자리만 확보)
A35: M1-5 | C35: 중음 | D35: 1 | I35: 훈련명 미정 (자리만 확보)
A36: M2-1 | B36: 허밍 | C36: 중음 | D36: 1
A37: M2-2 | C37: 중음 | D37: 1 | I37: 훈련명 미정 (자리만 확보)
A38: M2-3 | B38: 립트릴 | C38: 중음 | D38: 1
A39: M2-4 | C39: 중음 | D39: 1 | I39: 훈련명 미정 (자리만 확보)
A40: M2-5 | C40: 중음 | D40: 1 | I40: 훈련명 미정 (자리만 확보)
...
